Workbook

Sheet Tổng hợp
A1: KIỂM TRA CATALOGUE – thư mục "Catalog Sua" (01/10/2026)
A2: Số lỗi theo file và mức độ (công thức đếm từ sheet "Danh sách lỗi"; một dòng lỗi chung cho nhiều file được tính cho từng file).
A4: Thư mục | B4: File (bản cũ) | C4: Số trang | D4: 1-Nghiêm trọng | E4: 2-Lỗi | F4: 3-Cần anh xác nhận | G4: 4-Nhỏ (trình bày) | H4: Tổng | I4: Anh đã duyệt "Sửa" | J4: Bản mới (để sửa)
A5: Giếng | B5: Aquaris bơm giếng SA 1_300dpi_75%.pdf | C5: 10 | D5: =COUNTIFS('Danh sách lỗi'!$C$3:$C$178,"*"&$B5&"*",'Danh sách lỗi'!$F$3:$F$178,"1-Nghiêm trọng") -> 5 | E5: =COUNTIFS('Danh sách lỗi'!$C$3:$C$178,"*"&$B5&"*",'Danh sách lỗi'!$F$3:$F$178,"2-Lỗi") -> 6 | F5: =COUNTIFS('Danh sách lỗi'!$C$3:$C$178,"*"&$B5&"*",'Danh sách lỗi'!$F$3:$F$178,"3-Cần anh xác nhận") -> 1 | G5: =COUNTIFS('Danh sách lỗi'!$C$3:$C$178,"*"&$B5&"*",'Danh sách lỗi'!$F$3:$F$178,"4-Nhỏ (trình bày)") -> 3 | H5: =SUM(D5:G5) -> 15 | I5: =COUNTIFS('Danh sách lỗi'!$C$3:$C$178,"*"&$B5&"*",'Danh sách lỗi'!$K$3:$K$178,"Sửa") -> 0 | J5: BẢN MỚI 01-10-2026\Giếng\Aquaris bơm giếng SA 1_300dpi_75% (bản mới).pdf
A6: Giếng | B6: Aquaris bơm giếng SP 1_300dpi_75%.pdf | C6: 32 | D6: =COUNTIFS('Danh sách lỗi'!$C$3:$C$178,"*"&$B6&"*",'Danh sách lỗi'!$F$3:$F$178,"1-Nghiêm trọng") -> 9 | E6: =COUNTIFS('Danh sách lỗi'!$C$3:$C$178,"*"&$B6&"*",'Danh sách lỗi'!$F$3:$F$178,"2-Lỗi") -> 18 | F6: =COUNTIFS('Danh sách lỗi'!$C$3:$C$178,"*"&$B6&"*",'Danh sách lỗi'!$F$3:$F$178,"3-Cần anh xác nhận") -> 12 | G6: =COUNTIFS('Danh sách lỗi'!$C$3:$C$178,"*"&$B6&"*",'Danh sách lỗi'!$F$3:$F$178,"4-Nhỏ (trình bày)") -> 4 | H6: =SUM(D6:G6) -> 43 | I6: =COUNTIFS('Danh sách lỗi'!$C$3:$C$178,"*"&$B6&"*",'Danh sách lỗi'!$K$3:$K$178,"Sửa") -> 0 | J6: BẢN MỚI 01-10-2026\Giếng\Aquaris bơm giếng SP 1_300dpi_75% (bản mới).pdf
A7: Giếng | B7: Perotac bơm giếng SA_compressed.pdf | C7: 11 | D7: =COUNTIFS('Danh sách lỗi'!$C$3:$C$178,"*"&$B7&"*",'Danh sách lỗi'!$F$3:$F$178,"1-Nghiêm trọng") -> 4 | E7: =COUNTIFS('Danh sách lỗi'!$C$3:$C$178,"*"&$B7&"*",'Danh sách lỗi'!$F$3:$F$178,"2-Lỗi") -> 5 | F7: =COUNTIFS('Danh sách lỗi'!$C$3:$C$178,"*"&$B7&"*",'Danh sách lỗi'!$F$3:$F$178,"3-Cần anh xác nhận") -> 2 | G7: =COUNTIFS('Danh sách lỗi'!$C$3:$C$178,"*"&$B7&"*",'Danh sách lỗi'!$F$3:$F$178,"4-Nhỏ (trình bày)") -> 0 | H7: =SUM(D7:G7) -> 11 | I7: =COUNTIFS('Danh sách lỗi'!$C$3:$C$178,"*"&$B7&"*",'Danh sách lỗi'!$K$3:$K$178,"Sửa") -> 0 | J7: BẢN MỚI 01-10-2026\Giếng\Perotac bơm giếng SA_compressed (bản mới).pdf
A8: Giếng | B8: Perotac bơm giếng SP_compressed.pdf | C8: 12 | D8: =COUNTIFS('Danh sách lỗi'!$C$3:$C$178,"*"&$B8&"*",'Danh sách lỗi'!$F$3:$F$178,"1-Nghiêm trọng") -> 3 | E8: =COUNTIFS('Danh sách lỗi'!$C$3:$C$178,"*"&$B8&"*",'Danh sách lỗi'!$F$3:$F$178,"2-Lỗi") -> 0 | F8: =COUNTIFS('Danh sách lỗi'!$C$3:$C$178,"*"&$B8&"*",'Danh sách lỗi'!$F$3:$F$178,"3-Cần anh xác nhận") -> 3 | G8: =COUNTIFS('Danh sách lỗi'!$C$3:$C$178,"*"&$B8&"*",'Danh sách lỗi'!$F$3:$F$178,"4-Nhỏ (trình bày)") -> 1 | H8: =SUM(D8:G8) -> 7 | I8: =COUNTIFS('Danh sách lỗi'!$C$3:$C$178,"*"&$B8&"*",'Danh sách lỗi'!$K$3:$K$178,"Sửa") -> 0 | J8: BẢN MỚI 01-10-2026\Giếng\Perotac bơm giếng SP_compressed (bản mới).pdf
A9: Giếng | B9: Redpump gieng SL_compressed.pdf | C9: 11 | D9: =COUNTIFS('Danh sách lỗi'!$C$3:$C$178,"*"&$B9&"*",'Danh sách lỗi'!$F$3:$F$178,"1-Nghiêm trọng") -> 4 | E9: =COUNTIFS('Danh sách lỗi'!$C$3:$C$178,"*"&$B9&"*",'Danh sách lỗi'!$F$3:$F$178,"2-Lỗi") -> 5 | F9: =COUNTIFS('Danh sách lỗi'!$C$3:$C$178,"*"&$B9&"*",'Danh sách lỗi'!$F$3:$F$178,"3-Cần anh xác nhận") -> 2 | G9: =COUNTIFS('Danh sách lỗi'!$C$3:$C$178,"*"&$B9&"*",'Danh sách lỗi'!$F$3:$F$178,"4-Nhỏ (trình bày)") -> 1 | H9: =SUM(D9:G9) -> 12 | I9: =COUNTIFS('Danh sách lỗi'!$C$3:$C$178,"*"&$B9&"*",'Danh sách lỗi'!$K$3:$K$178,"Sửa") -> 0 | J9: BẢN MỚI 01-10-2026\Giếng\Redpump gieng SL_compressed (bản mới).pdf
A10: Nước thải | B10: Aquaris FS_300dpi_75%.pdf | C10: 4 | D10: =COUNTIFS('Danh sách lỗi'!$C$3:$C$178,"*"&$B10&"*",'Danh sách lỗi'!$F$3:$F$178,"1-Nghiêm trọng") -> 0 | E10: =COUNTIFS('Danh sách lỗi'!$C$3:$C$178,"*"&$B10&"*",'Danh sách lỗi'!$F$3:$F$178,"2-Lỗi") -> 0 | F10: =COUNTIFS('Danh sách lỗi'!$C$3:$C$178,"*"&$B10&"*",'Danh sách lỗi'!$F$3:$F$178,"3-Cần anh xác nhận") -> 1 | G10: =COUNTIFS('Danh sách lỗi'!$C$3:$C$178,"*"&$B10&"*",'Danh sách lỗi'!$F$3:$F$178,"4-Nhỏ (trình bày)") -> 3 | H10: =SUM(D10:G10) -> 4 | I10: =COUNTIFS('Danh sách lỗi'!$C$3:$C$178,"*"&$B10&"*",'Danh sách lỗi'!$K$3:$K$178,"Sửa") -> 0 | J10: BẢN MỚI 01-10-2026\Nước thải\Aquaris FS_300dpi_75% (bản mới).pdf
A11: Nước thải | B11: Catalog bơm nước thải Aquaris FS.pdf | C11: 1 | D11: =COUNTIFS('Danh sách lỗi'!$C$3:$C$178,"*"&$B11&"*",'Danh sách lỗi'!$F$3:$F$178,"1-Nghiêm trọng") -> 0 | E11: =COUNTIFS('Danh sách lỗi'!$C$3:$C$178,"*"&$B11&"*",'Danh sách lỗi'!$F$3:$F$178,"2-Lỗi") -> 3 | F11: =COUNTIFS('Danh sách lỗi'!$C$3:$C$178,"*"&$B11&"*",'Danh sách lỗi'!$F$3:$F$178,"3-Cần anh xác nhận") -> 2 | G11: =COUNTIFS('Danh sách lỗi'!$C$3:$C$178,"*"&$B11&"*",'Danh sách lỗi'!$F$3:$F$178,"4-Nhỏ (trình bày)") -> 1 | H11: =SUM(D11:G11) -> 6 | I11: =COUNTIFS('Danh sách lỗi'!$C$3:$C$178,"*"&$B11&"*",'Danh sách lỗi'!$K$3:$K$178,"Sửa") -> 0 | J11: BẢN MỚI 01-10-2026\Nước thải\Catalog bơm nước thải Aquaris FS (bản mới).pdf
A12: Nước thải | B12: Catalog cắt rác Aquaris WC.pdf | C12: 8 | D12: =COUNTIFS('Danh sách lỗi'!$C$3:$C$178,"*"&$B12&"*",'Danh sách lỗi'!$F$3:$F$178,"1-Nghiêm trọng") -> 0 | E12: =COUNTIFS('Danh sách lỗi'!$C$3:$C$178,"*"&$B12&"*",'Danh sách lỗi'!$F$3:$F$178,"2-Lỗi") -> 6 | F12: =COUNTIFS('Danh sách lỗi'!$C$3:$C$178,"*"&$B12&"*",'Danh sách lỗi'!$F$3:$F$178,"3-Cần anh xác nhận") -> 4 | G12: =COUNTIFS('Danh sách lỗi'!$C$3:$C$178,"*"&$B12&"*",'Danh sách lỗi'!$F$3:$F$178,"4-Nhỏ (trình bày)") -> 2 | H12: =SUM(D12:G12) -> 12 | I12: =COUNTIFS('Danh sách lỗi'!$C$3:$C$178,"*"&$B12&"*",'Danh sách lỗi'!$K$3:$K$178,"Sửa") -> 0 | J12: BẢN MỚI 01-10-2026\Nước thải\Catalog cắt rác Aquaris WC (bản mới).pdf
A13: Nước thải | B13: Catalog cắt rác perotac.pdf | C13: 8 | D13: =COUNTIFS('Danh sách lỗi'!$C$3:$C$178,"*"&$B13&"*",'Danh sách lỗi'!$F$3:$F$178,"1-Nghiêm trọng") -> 0 | E13: =COUNTIFS('Danh sách lỗi'!$C$3:$C$178,"*"&$B13&"*",'Danh sách lỗi'!$F$3:$F$178,"2-Lỗi") -> 6 | F13: =COUNTIFS('Danh sách lỗi'!$C$3:$C$178,"*"&$B13&"*",'Danh sách lỗi'!$F$3:$F$178,"3-Cần anh xác nhận") -> 4 | G13: =COUNTIFS('Danh sách lỗi'!$C$3:$C$178,"*"&$B13&"*",'Danh sách lỗi'!$F$3:$F$178,"4-Nhỏ (trình bày)") -> 2 | H13: =SUM(D13:G13) -> 12 | I13: =COUNTIFS('Danh sách lỗi'!$C$3:$C$178,"*"&$B13&"*",'Danh sách lỗi'!$K$3:$K$178,"Sửa") -> 0 | J13: BẢN MỚI 01-10-2026\Nước thải\Catalog cắt rác perotac (bản mới).pdf
A14: Nước thải | B14: Catalog cắt rác redpump.pdf | C14: 8 | D14: =COUNTIFS('Danh sách lỗi'!$C$3:$C$178,"*"&$B14&"*",'Danh sách lỗi'!$F$3:$F$178,"1-Nghiêm trọng") -> 0 | E14: =COUNTIFS('Danh sách lỗi'!$C$3:$C$178,"*"&$B14&"*",'Danh sách lỗi'!$F$3:$F$178,"2-Lỗi") -> 6 | F14: =COUNTIFS('Danh sách lỗi'!$C$3:$C$178,"*"&$B14&"*",'Danh sách lỗi'!$F$3:$F$178,"3-Cần anh xác nhận") -> 4 | G14: =COUNTIFS('Danh sách lỗi'!$C$3:$C$178,"*"&$B14&"*",'Danh sách lỗi'!$F$3:$F$178,"4-Nhỏ (trình bày)") -> 2 | H14: =SUM(D14:G14) -> 12 | I14: =COUNTIFS('Danh sách lỗi'!$C$3:$C$178,"*"&$B14&"*",'Danh sách lỗi'!$K$3:$K$178,"Sửa") -> 0 | J14: BẢN MỚI 01-10-2026\Nước thải\Catalog cắt rác redpump (bản mới).pdf
A15: Nước thải | B15: Catalogue perotac.xlsx | C15: Excel | D15: =COUNTIFS('Danh sách lỗi'!$C$3:$C$178,"*"&$B15&"*",'Danh sách lỗi'!$F$3:$F$178,"1-Nghiêm trọng") -> 0 | E15: =COUNTIFS('Danh sách lỗi'!$C$3:$C$178,"*"&$B15&"*",'Danh sách lỗi'!$F$3:$F$178,"2-Lỗi") -> 4 | F15: =COUNTIFS('Danh sách lỗi'!$C$3:$C$178,"*"&$B15&"*",'Danh sách lỗi'!$F$3:$F$178,"3-Cần anh xác nhận") -> 2 | G15: =COUNTIFS('Danh sách lỗi'!$C$3:$C$178,"*"&$B15&"*",'Danh sách lỗi'!$F$3:$F$178,"4-Nhỏ (trình bày)") -> 1 | H15: =SUM(D15:G15) -> 7 | I15: =COUNTIFS('Danh sách lỗi'!$C$3:$C$178,"*"&$B15&"*",'Danh sách lỗi'!$K$3:$K$178,"Sửa") -> 0 | J15: BẢN MỚI 01-10-2026\Nước thải\Catalogue perotac (bản mới).xlsx
A16: Nước thải | B16: KTZ - LH Perotac.pdf | C16: 7 | D16: =COUNTIFS('Danh sách lỗi'!$C$3:$C$178,"*"&$B16&"*",'Danh sách lỗi'!$F$3:$F$178,"1-Nghiêm trọng") -> 0 | E16: =COUNTIFS('Danh sách lỗi'!$C$3:$C$178,"*"&$B16&"*",'Danh sách lỗi'!$F$3:$F$178,"2-Lỗi") -> 5 | F16: =COUNTIFS('Danh sách lỗi'!$C$3:$C$178,"*"&$B16&"*",'Danh sách lỗi'!$F$3:$F$178,"3-Cần anh xác nhận") -> 1 | G16: =COUNTIFS('Danh sách lỗi'!$C$3:$C$178,"*"&$B16&"*",'Danh sách lỗi'!$F$3:$F$178,"4-Nhỏ (trình bày)") -> 1 | H16: =SUM(D16:G16) -> 7 | I16: =COUNTIFS('Danh sách lỗi'!$C$3:$C$178,"*"&$B16&"*",'Danh sách lỗi'!$K$3:$K$178,"Sửa") -> 0 | J16: BẢN MỚI 01-10-2026\Nước thải\KTZ - LH Perotac (bản mới).pdf
A17: Nước thải | B17: KTZ - LH Redpump.pdf | C17: 7 | D17: =COUNTIFS('Danh sách lỗi'!$C$3:$C$178,"*"&$B17&"*",'Danh sách lỗi'!$F$3:$F$178,"1-Nghiêm trọng") -> 0 | E17: =COUNTIFS('Danh sách lỗi'!$C$3:$C$178,"*"&$B17&"*",'Danh sách lỗi'!$F$3:$F$178,"2-Lỗi") -> 5 | F17: =COUNTIFS('Danh sách lỗi'!$C$3:$C$178,"*"&$B17&"*",'Danh sách lỗi'!$F$3:$F$178,"3-Cần anh xác nhận") -> 1 | G17: =COUNTIFS('Danh sách lỗi'!$C$3:$C$178,"*"&$B17&"*",'Danh sách lỗi'!$F$3:$F$178,"4-Nhỏ (trình bày)") -> 1 | H17: =SUM(D17:G17) -> 7 | I17: =COUNTIFS('Danh sách lỗi'!$C$3:$C$178,"*"&$B17&"*",'Danh sách lỗi'!$K$3:$K$178,"Sửa") -> 0 | J17: BẢN MỚI 01-10-2026\Nước thải\KTZ - LH Redpump (bản mới).pdf
A18: Thổi khí | B18: May thoi khi Perotac_300dpi_75%.pdf | C18: 29 | D18: =COUNTIFS('Danh sách lỗi'!$C$3:$C$178,"*"&$B18&"*",'Danh sách lỗi'!$F$3:$F$178,"1-Nghiêm trọng") -> 0 | E18: =COUNTIFS('Danh sách lỗi'!$C$3:$C$178,"*"&$B18&"*",'Danh sách lỗi'!$F$3:$F$178,"2-Lỗi") -> 2 | F18: =COUNTIFS('Danh sách lỗi'!$C$3:$C$178,"*"&$B18&"*",'Danh sách lỗi'!$F$3:$F$178,"3-Cần anh xác nhận") -> 1 | G18: =COUNTIFS('Danh sách lỗi'!$C$3:$C$178,"*"&$B18&"*",'Danh sách lỗi'!$F$3:$F$178,"4-Nhỏ (trình bày)") -> 5 | H18: =SUM(D18:G18) -> 8 | I18: =COUNTIFS('Danh sách lỗi'!$C$3:$C$178,"*"&$B18&"*",'Danh sách lỗi'!$K$3:$K$178,"Sửa") -> 0 | J18: BẢN MỚI 01-10-2026\Thổi khí\May thoi khi Perotac_300dpi_75% (bản mới).pdf
A19: Thổi khí | B19: Perotac Root_300dpi_75%.pdf | C19: 18 | D19: =COUNTIFS('Danh sách lỗi'!$C$3:$C$178,"*"&$B19&"*",'Danh sách lỗi'!$F$3:$F$178,"1-Nghiêm trọng") -> 3 | E19: =COUNTIFS('Danh sách lỗi'!$C$3:$C$178,"*"&$B19&"*",'Danh sách lỗi'!$F$3:$F$178,"2-Lỗi") -> 8 | F19: =COUNTIFS('Danh sách lỗi'!$C$3:$C$178,"*"&$B19&"*",'Danh sách lỗi'!$F$3:$F$178,"3-Cần anh xác nhận") -> 3 | G19: =COUNTIFS('Danh sách lỗi'!$C$3:$C$178,"*"&$B19&"*",'Danh sách lỗi'!$F$3:$F$178,"4-Nhỏ (trình bày)") -> 0 | H19: =SUM(D19:G19) -> 14 | I19: =COUNTIFS('Danh sách lỗi'!$C$3:$C$178,"*"&$B19&"*",'Danh sách lỗi'!$K$3:$K$178,"Sửa") -> 0 | J19: BẢN MỚI 01-10-2026\Thổi khí\Perotac Root_300dpi_75% (bản mới).pdf
A20: Trục đứng | B20: Bơm trục đứng CDLF Aquaris.pdf | C20: 12 | D20: =COUNTIFS('Danh sách lỗi'!$C$3:$C$178,"*"&$B20&"*",'Danh sách lỗi'!$F$3:$F$178,"1-Nghiêm trọng") -> 1 | E20: =COUNTIFS('Danh sách lỗi'!$C$3:$C$178,"*"&$B20&"*",'Danh sách lỗi'!$F$3:$F$178,"2-Lỗi") -> 5 | F20: =COUNTIFS('Danh sách lỗi'!$C$3:$C$178,"*"&$B20&"*",'Danh sách lỗi'!$F$3:$F$178,"3-Cần anh xác nhận") -> 0 | G20: =COUNTIFS('Danh sách lỗi'!$C$3:$C$178,"*"&$B20&"*",'Danh sách lỗi'!$F$3:$F$178,"4-Nhỏ (trình bày)") -> 1 | H20: =SUM(D20:G20) -> 7 | I20: =COUNTIFS('Danh sách lỗi'!$C$3:$C$178,"*"&$B20&"*",'Danh sách lỗi'!$K$3:$K$178,"Sửa") -> 0 | J20: BẢN MỚI 01-10-2026\Trục đứng\Bơm trục đứng CDLF Aquaris (bản mới).pdf
A21: Trục đứng | B21: Bơm trục đứng Perotac CDLF.pdf | C21: 12 | D21: =COUNTIFS('Danh sách lỗi'!$C$3:$C$178,"*"&$B21&"*",'Danh sách lỗi'!$F$3:$F$178,"1-Nghiêm trọng") -> 1 | E21: =COUNTIFS('Danh sách lỗi'!$C$3:$C$178,"*"&$B21&"*",'Danh sách lỗi'!$F$3:$F$178,"2-Lỗi") -> 5 | F21: =COUNTIFS('Danh sách lỗi'!$C$3:$C$178,"*"&$B21&"*",'Danh sách lỗi'!$F$3:$F$178,"3-Cần anh xác nhận") -> 1 | G21: =COUNTIFS('Danh sách lỗi'!$C$3:$C$178,"*"&$B21&"*",'Danh sách lỗi'!$F$3:$F$178,"4-Nhỏ (trình bày)") -> 1 | H21: =SUM(D21:G21) -> 8 | I21: =COUNTIFS('Danh sách lỗi'!$C$3:$C$178,"*"&$B21&"*",'Danh sách lỗi'!$K$3:$K$178,"Sửa") -> 0 | J21: BẢN MỚI 01-10-2026\Trục đứng\Bơm trục đứng Perotac CDLF (bản mới).pdf
A22: Trục đứng | B22: Inline IRG Perotac.pdf | C22: 3 | D22: =COUNTIFS('Danh sách lỗi'!$C$3:$C$178,"*"&$B22&"*",'Danh sách lỗi'!$F$3:$F$178,"1-Nghiêm trọng") -> 2 | E22: =COUNTIFS('Danh sách lỗi'!$C$3:$C$178,"*"&$B22&"*",'Danh sách lỗi'!$F$3:$F$178,"2-Lỗi") -> 1 | F22: =COUNTIFS('Danh sách lỗi'!$C$3:$C$178,"*"&$B22&"*",'Danh sách lỗi'!$F$3:$F$178,"3-Cần anh xác nhận") -> 1 | G22: =COUNTIFS('Danh sách lỗi'!$C$3:$C$178,"*"&$B22&"*",'Danh sách lỗi'!$F$3:$F$178,"4-Nhỏ (trình bày)") -> 0 | H22: =SUM(D22:G22) -> 4 | I22: =COUNTIFS('Danh sách lỗi'!$C$3:$C$178,"*"&$B22&"*",'Danh sách lỗi'!$K$3:$K$178,"Sửa") -> 0 | J22: BẢN MỚI 01-10-2026\Trục đứng\Inline IRG Perotac (bản mới).pdf
A23: Trục ngang | B23: 3M Aquaris.pdf | C23: 2 | D23: =COUNTIFS('Danh sách lỗi'!$C$3:$C$178,"*"&$B23&"*",'Danh sách lỗi'!$F$3:$F$178,"1-Nghiêm trọng") -> 0 | E23: =COUNTIFS('Danh sách lỗi'!$C$3:$C$178,"*"&$B23&"*",'Danh sách lỗi'!$F$3:$F$178,"2-Lỗi") -> 2 | F23: =COUNTIFS('Danh sách lỗi'!$C$3:$C$178,"*"&$B23&"*",'Danh sách lỗi'!$F$3:$F$178,"3-Cần anh xác nhận") -> 0 | G23: =COUNTIFS('Danh sách lỗi'!$C$3:$C$178,"*"&$B23&"*",'Danh sách lỗi'!$F$3:$F$178,"4-Nhỏ (trình bày)") -> 1 | H23: =SUM(D23:G23) -> 3 | I23: =COUNTIFS('Danh sách lỗi'!$C$3:$C$178,"*"&$B23&"*",'Danh sách lỗi'!$K$3:$K$178,"Sửa") -> 0 | J23: BẢN MỚI 01-10-2026\Trục ngang\3M Aquaris (bản mới).pdf
A24: Trục ngang | B24: 3M Perotac.pdf | C24: 2 | D24: =COUNTIFS('Danh sách lỗi'!$C$3:$C$178,"*"&$B24&"*",'Danh sách lỗi'!$F$3:$F$178,"1-Nghiêm trọng") -> 0 | E24: =COUNTIFS('Danh sách lỗi'!$C$3:$C$178,"*"&$B24&"*",'Danh sách lỗi'!$F$3:$F$178,"2-Lỗi") -> 2 | F24: =COUNTIFS('Danh sách lỗi'!$C$3:$C$178,"*"&$B24&"*",'Danh sách lỗi'!$F$3:$F$178,"3-Cần anh xác nhận") -> 0 | G24: =COUNTIFS('Danh sách lỗi'!$C$3:$C$178,"*"&$B24&"*",'Danh sách lỗi'!$F$3:$F$178,"4-Nhỏ (trình bày)") -> 1 | H24: =SUM(D24:G24) -> 3 | I24: =COUNTIFS('Danh sách lỗi'!$C$3:$C$178,"*"&$B24&"*",'Danh sách lỗi'!$K$3:$K$178,"Sửa") -> 0 | J24: BẢN MỚI 01-10-2026\Trục ngang\3M Perotac (bản mới).pdf
A25: Trục ngang | B25: Aquaris truc ngang CM.pdf | C25: 4 | D25: =COUNTIFS('Danh sách lỗi'!$C$3:$C$178,"*"&$B25&"*",'Danh sách lỗi'!$F$3:$F$178,"1-Nghiêm trọng") -> 0 | E25: =COUNTIFS('Danh sách lỗi'!$C$3:$C$178,"*"&$B25&"*",'Danh sách lỗi'!$F$3:$F$178,"2-Lỗi") -> 4 | F25: =COUNTIFS('Danh sách lỗi'!$C$3:$C$178,"*"&$B25&"*",'Danh sách lỗi'!$F$3:$F$178,"3-Cần anh xác nhận") -> 1 | G25: =COUNTIFS('Danh sách lỗi'!$C$3:$C$178,"*"&$B25&"*",'Danh sách lỗi'!$F$3:$F$178,"4-Nhỏ (trình bày)") -> 2 | H25: =SUM(D25:G25) -> 7 | I25: =COUNTIFS('Danh sách lỗi'!$C$3:$C$178,"*"&$B25&"*",'Danh sách lỗi'!$K$3:$K$178,"Sửa") -> 0 | J25: BẢN MỚI 01-10-2026\Trục ngang\Aquaris truc ngang CM (bản mới).pdf
A26: Trục ngang | B26: CDX Perotac.pdf | C26: 5 | D26: =COUNTIFS('Danh sách lỗi'!$C$3:$C$178,"*"&$B26&"*",'Danh sách lỗi'!$F$3:$F$178,"1-Nghiêm trọng") -> 1 | E26: =COUNTIFS('Danh sách lỗi'!$C$3:$C$178,"*"&$B26&"*",'Danh sách lỗi'!$F$3:$F$178,"2-Lỗi") -> 3 | F26: =COUNTIFS('Danh sách lỗi'!$C$3:$C$178,"*"&$B26&"*",'Danh sách lỗi'!$F$3:$F$178,"3-Cần anh xác nhận") -> 1 | G26: =COUNTIFS('Danh sách lỗi'!$C$3:$C$178,"*"&$B26&"*",'Danh sách lỗi'!$F$3:$F$178,"4-Nhỏ (trình bày)") -> 2 | H26: =SUM(D26:G26) -> 7 | I26: =COUNTIFS('Danh sách lỗi'!$C$3:$C$178,"*"&$B26&"*",'Danh sách lỗi'!$K$3:$K$178,"Sửa") -> 0 | J26: BẢN MỚI 01-10-2026\Trục ngang\CDX Perotac (bản mới).pdf
A27: Trục ngang | B27: Catalogue DWO.xlsx | C27: Excel | D27: =COUNTIFS('Danh sách lỗi'!$C$3:$C$178,"*"&$B27&"*",'Danh sách lỗi'!$F$3:$F$178,"1-Nghiêm trọng") -> 0 | E27: =COUNTIFS('Danh sách lỗi'!$C$3:$C$178,"*"&$B27&"*",'Danh sách lỗi'!$F$3:$F$178,"2-Lỗi") -> 3 | F27: =COUNTIFS('Danh sách lỗi'!$C$3:$C$178,"*"&$B27&"*",'Danh sách lỗi'!$F$3:$F$178,"3-Cần anh xác nhận") -> 1 | G27: =COUNTIFS('Danh sách lỗi'!$C$3:$C$178,"*"&$B27&"*",'Danh sách lỗi'!$F$3:$F$178,"4-Nhỏ (trình bày)") -> 1 | H27: =SUM(D27:G27) -> 5 | I27: =COUNTIFS('Danh sách lỗi'!$C$3:$C$178,"*"&$B27&"*",'Danh sách lỗi'!$K$3:$K$178,"Sửa") -> 0 | J27: BẢN MỚI 01-10-2026\Trục ngang\Catalogue DWO (bản mới).xlsx
A28: Trục ngang | B28: bơm trục ngnag perotac model CM.pdf | C28: 2 | D28: =COUNTIFS('Danh sách lỗi'!$C$3:$C$178,"*"&$B28&"*",'Danh sách lỗi'!$F$3:$F$178,"1-Nghiêm trọng") -> 2 | E28: =COUNTIFS('Danh sách lỗi'!$C$3:$C$178,"*"&$B28&"*",'Danh sách lỗi'!$F$3:$F$178,"2-Lỗi") -> 2 | F28: =COUNTIFS('Danh sách lỗi'!$C$3:$C$178,"*"&$B28&"*",'Danh sách lỗi'!$F$3:$F$178,"3-Cần anh xác nhận") -> 0 | G28: =COUNTIFS('Danh sách lỗi'!$C$3:$C$178,"*"&$B28&"*",'Danh sách lỗi'!$F$3:$F$178,"4-Nhỏ (trình bày)") -> 2 | H28: =SUM(D28:G28) -> 6 | I28: =COUNTIFS('Danh sách lỗi'!$C$3:$C$178,"*"&$B28&"*",'Danh sách lỗi'!$K$3:$K$178,"Sửa") -> 0 | J28: BẢN MỚI 01-10-2026\Trục ngang\bơm trục ngnag perotac model CM (bản mới).pdf
A29: Trục ngang | B29: bơm trục ngnag redpump model CM_300dpi_75%.pdf | C29: 2 | D29: =COUNTIFS('Danh sách lỗi'!$C$3:$C$178,"*"&$B29&"*",'Danh sách lỗi'!$F$3:$F$178,"1-Nghiêm trọng") -> 2 | E29: =COUNTIFS('Danh sách lỗi'!$C$3:$C$178,"*"&$B29&"*",'Danh sách lỗi'!$F$3:$F$178,"2-Lỗi") -> 2 | F29: =COUNTIFS('Danh sách lỗi'!$C$3:$C$178,"*"&$B29&"*",'Danh sách lỗi'!$F$3:$F$178,"3-Cần anh xác nhận") -> 0 | G29: =COUNTIFS('Danh sách lỗi'!$C$3:$C$178,"*"&$B29&"*",'Danh sách lỗi'!$F$3:$F$178,"4-Nhỏ (trình bày)") -> 2 | H29: =SUM(D29:G29) -> 6 | I29: =COUNTIFS('Danh sách lỗi'!$C$3:$C$178,"*"&$B29&"*",'Danh sách lỗi'!$K$3:$K$178,"Sửa") -> 0 | J29: BẢN MỚI 01-10-2026\Trục ngang\bơm trục ngnag redpump model CM_300dpi_75% (bản mới).pdf
A30: Dòng ghi chú chung (không gắn file cụ thể) | D30: =COUNTIFS('Danh sách lỗi'!$C$3:$C$178,"Redpump (*",'Danh sách lỗi'!$F$3:$F$178,"1-Nghiêm trọng") -> 0 | E30: =COUNTIFS('Danh sách lỗi'!$C$3:$C$178,"Redpump (*",'Danh sách lỗi'!$F$3:$F$178,"2-Lỗi") -> 0 | F30: =COUNTIFS('Danh sách lỗi'!$C$3:$C$178,"Redpump (*",'Danh sách lỗi'!$F$3:$F$178,"3-Cần anh xác nhận") -> 1 | G30: =COUNTIFS('Danh sách lỗi'!$C$3:$C$178,"Redpump (*",'Danh sách lỗi'!$F$3:$F$178,"4-Nhỏ (trình bày)") -> 0 | H30: =SUM(D30:G30) -> 1
A31: Số dòng lỗi trong danh sách (mỗi dòng đếm 1 lần) | D31: =COUNTIF('Danh sách lỗi'!$F$3:$F$178,"1-Nghiêm trọng") -> 30 | E31: =COUNTIF('Danh sách lỗi'!$F$3:$F$178,"2-Lỗi") -> 79 | F31: =COUNTIF('Danh sách lỗi'!$F$3:$F$178,"3-Cần anh xác nhận") -> 36 | G31: =COUNTIF('Danh sách lỗi'!$F$3:$F$178,"4-Nhỏ (trình bày)") -> 31 | H31: =SUM(D31:G31) -> 176 | I31: =COUNTIF('Danh sách lỗi'!$K$3:$K$178,"Sửa") -> 0

Sheet Danh sách lỗi
A1: DANH SÁCH LỖI CATALOGUE – kiểm ngày 01/10/2026. Anh chỉ điền cột K "Anh duyệt" (chọn Sửa / Không sửa / Hỏi lại) và cột L nếu cần, ví dụ: K = Sửa, L = "sửa theo đề xuất". Em sẽ sửa trong thư mục "BẢN MỚI 01-10-2026".
A2: STT | B2: Thư mục | C2: File (bản cũ) | D2: Trang PDF | E2: Trang in | F2: Mức độ | G2: Vị trí / mục | H2: Đang ghi (lỗi) | I2: Đề xuất sửa | J2: Căn cứ kiểm | K2: Anh duyệt | L2: Ghi chú của anh
A3: 1 | B3: Giếng | C3: Aquaris bơm giếng SA 1_300dpi_75%.pdf | D3: 3 | E3: 01 | F3: 2-Lỗi | G3: Bảng 4SA2, dòng 4SA2/65 | H3: 4.0 kW = 5.0 HP | I3: 4.0 kW = 5.5 HP (như các trang khác) | J3: Đối chiếu kW↔HP trong cùng file
A4: 2 | B4: Giếng | C4: Aquaris bơm giếng SA 1_300dpi_75%.pdf | D4: 4 | E4: 02 | F4: 2-Lỗi | G4: Bảng 4SA3, hàng m³/h | H4: 1.1 m³/h ứng 20 l/min | I4: 1.2 m³/h | J4: 20 l/min × 0,06 = 1,2 m³/h
A5: 3 | B5: Giếng | C5: Aquaris bơm giếng SA 1_300dpi_75%.pdf | D5: 5 | E5: 03 | F5: 2-Lỗi | G5: Bảng 4SA4, hàng m³/h | H5: 5.0 m³/h ứng 90 l/min | I5: 5.4 m³/h | J5: 90 l/min × 0,06 = 5,4 m³/h
A6: 4 | B6: Giếng | C6: Aquaris bơm giếng SA 1_300dpi_75%.pdf | D6: 5 | E6: 03 | F6: 1-Nghiêm trọng | G6: Bảng 4SA4, dòng 4SA4/22, cột 3.0 m³/h (50 l/min) | H6: 103 (thấp hơn cả điểm 4.2 m³/h = 104) | I6: ≈129 | J6: Tỉ lệ cột áp/tầng các model cùng bảng (4SA4/16 = 94 → 5,9 m/tầng)
A7: 5 | B7: Giếng | C7: Aquaris bơm giếng SA 1_300dpi_75%.pdf | D7: 5 | E7: 03 | F7: 3-Cần anh xác nhận | G7: Bảng 4SA4, dòng 4SA4/40, cột 6.0 m³/h | H7: 98 | I7: ≈89 (4SA4/32 = 71, 4SA4/50 = 111 → 2,22 m/tầng) | J7: Tỉ lệ cột áp/tầng
A8: 6 | B8: Giếng | C8: Aquaris bơm giếng SA 1_300dpi_75%.pdf | D8: 6 | E8: 04 | F8: 2-Lỗi | G8: Bảng 4SA6, dòng 4SA6/11 | H8: 1.0 kW / 1.5 HP | I8: 1.1 kW / 1.5 HP | J8: Đối chiếu kW↔HP
A9: 7 | B9: Giếng | C9: Aquaris bơm giếng SA 1_300dpi_75%.pdf | D9: 6 | E9: 04 | F9: 1-Nghiêm trọng | G9: Bảng 4SA6, dòng 4SA6/36, cột 1.2 m³/h | H9: 281 (cao hơn cả điểm 0 = 227) | I9: ≈217 | J9: Tỉ lệ cột áp/tầng (4SA6/28 = 169, 4SA6/46 = 278)
A10: 8 | B10: Giếng | C10: Aquaris bơm giếng SA 1_300dpi_75%.pdf | D10: 7 | E10: 05 | F10: 2-Lỗi | G10: Bảng 4SA8, hàng m³/h | H10: 2.2 m³/h ứng 40 l/min | I10: 2.4 m³/h | J10: 40 l/min × 0,06 = 2,4 m³/h
A11: 9 | B11: Giếng | C11: Aquaris bơm giếng SA 1_300dpi_75%.pdf | D11: 7 | E11: 05 | F11: 2-Lỗi | G11: Bảng 4SA8, dòng 4SA8/8 | H11: 1.0 kW / 1.5 HP | I11: 1.1 kW / 1.5 HP | J11: Đối chiếu kW↔HP
A12: 10 | B12: Giếng | C12: Aquaris bơm giếng SA 1_300dpi_75%.pdf | D12: 7 | E12: 05 | F12: 1-Nghiêm trọng | G12: Bảng 4SA8, dòng "4SA8/24" | H12: Tên 4SA8/24 nhưng số liệu 162-153-137-114-72-14 là của 28 tầng; biểu đồ ghi 4SA8/28 | I12: Đổi tên thành 4SA8/28 (hoặc sửa số liệu nếu đúng là 24 tầng) | J12: 5,8 m/tầng ×28 = 162; nhãn biểu đồ
A13: 11 | B13: Giếng | C13: Aquaris bơm giếng SA 1_300dpi_75%.pdf | D13: 7 | E13: 05 | F13: 1-Nghiêm trọng | G13: Bảng 4SA8, dòng 4SA8/44, cột 4.8 m³/h | H13: 316 (cao hơn điểm 0 = 255) | I13: ≈216 (khớp đường cong biểu đồ) | J13: Tỉ lệ cột áp/tầng + biểu đồ
A14: 12 | B14: Giếng | C14: Aquaris bơm giếng SA 1_300dpi_75%.pdf | D14: 8 | E14: 06 | F14: 1-Nghiêm trọng | G14: Bảng 4SA10, dòng 4SA10/28, cột 1.8 m³/h | H14: 116 | I14: ≈166 | J14: Tỉ lệ cột áp/tầng (4SA10/23 = 136 → 5,9 m/tầng)
A15: 13 | B15: Giếng | C15: Aquaris bơm giếng SA 1_300dpi_75%.pdf | D15: 10 | E15: 08 | F15: 4-Nhỏ (trình bày) | G15: Bảng 4SA16, hàng l/min | H15: 230 / 265 / 360 ứng 14 / 16 / 22 m³/h | I15: 233 / 267 / 367 | J15: m³/h × 16,67
A16: 14 | B16: Giếng | C16: Aquaris bơm giếng SA 1_300dpi_75%.pdf | D16: 2 | F16: 4-Nhỏ (trình bày) | G16: Trang mục lục | H16: Tên model trong 6 ô không thẳng hàng | I16: Căn lại cho đều | J16: Xem ảnh trang
A17: 15 | B17: Giếng | C17: Aquaris bơm giếng SA 1_300dpi_75%.pdf | D17: cả file | F17: 4-Nhỏ (trình bày) | G17: Chữ chung | H17: "Kw", "KW", "Hp"; "Aquaris S.r.l"; "diameterϕ95mm" dính chữ | I17: kW, HP; S.r.l.; "diameter ϕ95 mm" | J17: Đọc trang
A18: 16 | B18: Giếng | C18: Aquaris bơm giếng SP 1_300dpi_75%.pdf | D18: 2 | F18: 2-Lỗi | G18: Mục lục | H18: Có mục "5SP5" nhưng catalogue không có trang 5SP5 | I18: Bỏ 5SP5 khỏi mục lục (hoặc bổ sung trang) | J18: Đối chiếu mục lục với các trang 08–12
A19: 17 | B19: Giếng | C19: Aquaris bơm giếng SP 1_300dpi_75%.pdf | D19: 3 | E19: 01 | F19: 2-Lỗi | G19: Bảng 3SP1, hàng l/min | H19: 6 l/min ứng 0.5 m³/h | I19: 8 l/min | J19: 0,5 m³/h = 8,3 l/min
A20: 18 | B20: Giếng | C20: Aquaris bơm giếng SP 1_300dpi_75%.pdf | D20: 3–4 | E20: 01–02 | F20: 3-Cần anh xác nhận | G20: Bảng 3SP1, 3SP2 – Outlet | H20: G2¼" cho bơm 3" (thân Ø70 mm) | I20: Kiểm lại cỡ ren (bơm 4" trong file ghi G1¼") | J20: Kích thước ren lớn hơn thân bơm
A21: 19 | B21: Giếng | C21: Aquaris bơm giếng SP 1_300dpi_75%.pdf | D21: 5 | E21: 03 | F21: 2-Lỗi | G21: Sơ đồ ký hiệu model 4SP2 | H21: "4 SP 2 23 - 11" với chú thích Motor power | I21: "23 - 1.1" (4SP2-23 là 1,1 kW) | J21: Bảng cùng trang
A22: 20 | B22: Giếng | C22: Aquaris bơm giếng SP 1_300dpi_75%.pdf | D22: 5 | E22: 03 | F22: 2-Lỗi | G22: Bảng 4SP2, hàng l/min | H22: 40 l/min ứng 2.5 m³/h | I22: 42 l/min (như trang 3SP1, 3SP2) | J22: 2,5 m³/h = 41,7 l/min
A23: 21 | B23: Giếng | C23: Aquaris bơm giếng SP 1_300dpi_75%.pdf | D23: 5 | E23: 03 | F23: 1-Nghiêm trọng | G23: Bảng 4SP2, dòng 4SP2-40, cột 2 m³/h | H23: 140 | I23: 160 | J23: Mọi model 4,0 m/tầng ở cột này
A24: 22 | B24: Giếng | C24: Aquaris bơm giếng SP 1_300dpi_75%.pdf | D24: 5 | E24: 03 | F24: 3-Cần anh xác nhận | G24: Bảng 4SP2, dòng 4SP2-18, cột 2.5 m³/h | H24: 66 | I24: ≈60 | J24: Tỉ lệ cột áp/tầng
A25: 23 | B25: Giếng | C25: Aquaris bơm giếng SP 1_300dpi_75%.pdf | D25: 9 | E25: 07 | F25: 3-Cần anh xác nhận | G25: Bảng 4SP14, dòng 4SP14-13, chiều dài | H25: 818 | I25: 815 (bước 50 mm/tầng) | J25: Cột Length các dòng khác
A26: 24 | B26: Giếng | C26: Aquaris bơm giếng SP 1_300dpi_75%.pdf | D26: 9 | E26: 07 | F26: 4-Nhỏ (trình bày) | G26: Bảng 4SP14, hàng l/min | H26: 166 / 266 | I26: 167 / 267 (như các trang khác) | J26: 10 m³/h = 166,7
A27: 25 | B27: Giếng | C27: Aquaris bơm giếng SP 1_300dpi_75%.pdf | D27: 10 | E27: 08 | F27: 1-Nghiêm trọng | G27: Bảng 5SP10, dòng thứ 4 | H27: "5SP10-18" (4 kW, 88 m) – trùng tên dòng 5SP10-18 (9,2 kW) | I27: 5SP10-08 | J27: 88 m = 8 tầng × 11 m; biểu đồ ghi 08-4.0
A28: 26 | B28: Giếng | C28: Aquaris bơm giếng SP 1_300dpi_75%.pdf | D28: 10 | E28: 08 | F28: 4-Nhỏ (trình bày) | G28: Biểu đồ 5SP10 | H28: Không có đường 5SP10-30 (cột áp vượt trục 300) | I28: Nới trục hoặc ghi chú | J28: Xem biểu đồ
A29: 27 | B29: Giếng | C29: Aquaris bơm giếng SP 1_300dpi_75%.pdf | D29: 11 | E29: 09 | F29: 1-Nghiêm trọng | G29: Bảng 5SP15, dòng 5SP15-22, cột 17 m³/h | H29: 147 | I29: ≈167 | J29: Mọi model 7,6 m/tầng ở cột này
A30: 28 | B30: Giếng | C30: Aquaris bơm giếng SP 1_300dpi_75%.pdf | D30: 13 | E30: 11 | F30: 2-Lỗi | G30: Sơ đồ ký hiệu model trang 5SP25 | H30: "5 SP 15 7 - 4" (chép từ trang 5SP15) | I30: Ví dụ model 5SP25 có trong bảng | J30: Đọc trang
... A59: 57 | B59: Giếng | C59: Aquaris bơm giếng SP 1_300dpi_75%.pdf | D59: 32 | E59: 30 | F59: 3-Cần anh xác nhận | G59: Bảng 10SP160, dòng 10SP160-03, cột 180 m³/h | H59: 52 | I59: ≈54 | J59: 18 m/tầng
A60: 58 | B60: Giếng | C60: Aquaris bơm giếng SP 1_300dpi_75%.pdf | D60: cả file | F60: 4-Nhỏ (trình bày) | G60: Chữ chung | H60: "Kw/KW/Hp"; tên model lúc có số 0 lúc không (4SP2-6 / 4SP3-06) | I60: Thống nhất kW, HP và cách ghi model | J60: Đọc trang
A61: 59 | B61: Giếng | C61: Perotac bơm giếng SA_compressed.pdf | D61: 1 | F61: 2-Lỗi | G61: Operating conditions | H61: "2SD minimum well diameter", "2.5SD minimum well diameter" | I61: 2SS / 2.5SS (bản Redpump đã ghi đúng 2SL) | J61: Tên dòng sản phẩm
A62: 60 | B62: Giếng | C62: Perotac bơm giếng SA_compressed.pdf; Redpump gieng SL_compressed.pdf | D62: 1 | F62: 2-Lỗi | G62: Biểu đồ 2.5SS1.5 / 2.5SL1.5 | H62: Nhãn ".../24" xuất hiện 2 lần; đường ≈46 m không có nhãn /17 | I62: Đổi nhãn thứ 2 thành 2.5SS1.5/17 (2.5SL1.5/17) | J62: Bảng cùng trang
A63: 61 | B63: Giếng | C63: Perotac bơm giếng SA_compressed.pdf; Redpump gieng SL_compressed.pdf | D63: 1 | F63: 2-Lỗi | G63: Bảng kích thước 2.5SS(M)1.5/24 – 2.5SL(M)1.5/24 | H63: P 779 + M 787 = 1566 nhưng T ghi 1546 | I63: Kiểm lại T (hoặc P/M) | J63: Cộng P+M các dòng khác đều khớp
A64: 62 | B64: Giếng | C64: Perotac bơm giếng SA_compressed.pdf; Redpump gieng SL_compressed.pdf | D64: 3 | F64: 1-Nghiêm trọng | G64: Bảng kích thước 3SS2 / 3SL2 | H64: 3SS2/11: T(T) 752 (444+288 = 732); 3SS2/15: T(T) 873 (535+308 = 843) | I64: 732; 843 | J64: T = P + M (các dòng khác đều khớp)
A65: 63 | B65: Giếng | C65: Perotac bơm giếng SA_compressed.pdf; Redpump gieng SL_compressed.pdf | D65: 3 | F65: 1-Nghiêm trọng | G65: Bảng khối lượng 3SS3 / 3SL3 | H65: 3SS3/26: M(T) 6.4 kg; 3SS3/31: M(T) 7.5 kg (tổng T(T) không khớp) | I65: 7.5 kg; 8.7 kg (cùng động cơ dài 408/448 mm như bảng 3SS2) | J65: T = P + M
A66: 64 | B66: Giếng | C66: Perotac bơm giếng SA_compressed.pdf; Redpump gieng SL_compressed.pdf | D66: 8 | F66: 1-Nghiêm trọng | G66: Bảng kích thước 4SA3 / 4SL3 | H66: 4SA3/10: T(S) 814 (490+329 = 819); 4SA3/35: T(S) 1664 (1194+594 = 1788, chép từ 4SA4/28) | I66: 819; 1788 | J66: T = P + M
A67: 65 | B67: Giếng | C67: Perotac bơm giếng SA_compressed.pdf; Redpump gieng SL_compressed.pdf | D67: 9 | F67: 1-Nghiêm trọng | G67: Bảng kích thước 4SA8 / 4SL8, dòng 4SA8/6 | H67: P 475 mm / 3.3 kg nhưng T(S) 872, T(T) 857, 12.6 kg, 11.9 kg (lệch 38 mm và 0.6 kg) | I67: Đối chiếu tài liệu NCC (nếu T đúng thì P = 513 mm / 3.9 kg) | J67: T = P + M
A68: 66 | B68: Giếng | C68: Perotac bơm giếng SA_compressed.pdf; Redpump gieng SL_compressed.pdf | D68: 9 | F68: 2-Lỗi | G68: Bảng kích thước 4SA12 / 4SL12, dòng 4SA12/32 | H68: P 2143 + M 908 = 3051 nhưng T(T) ghi 3020 | I68: P = 2112 (1944 + 3×56) hoặc T = 3051 | J68: T = P + M
...

Sheet Cách kiểm & lưu ý
A1: CÁCH KIỂM TRA VÀ LƯU Ý
A3: PHẠM VI | B3: Toàn bộ 25 file trong thư mục "Catalog Sua": 23 PDF (210 trang) + 2 Excel. Không sửa file gốc.
A4: BẢN MỚI | B4: Đã tạo thư mục "Catalog Sua\BẢN MỚI 01-10-2026" giữ nguyên cấu trúc 5 thư mục con; mỗi file là bản sao y hệt bản cũ, tên thêm " (bản mới)". Đã so mã băm SHA-256: 25/25 file trùng khớp 100% với bản cũ (font, màu, bố cục giữ nguyên). Khi anh duyệt lỗi nào, em sửa trong bản mới, giữ đúng font/màu/cỡ chữ của bản cũ.
A5: CÁCH KIỂM | B5: 1) Đọc lớp chữ của các PDF có chữ (cắt rác WC, máy thổi khí GB, FS A3, CM Aquaris, KTZ-LH). 2) PDF dạng ảnh: nhận dạng chữ (OCR) + xem ảnh từng trang. 3) Bảng số liệu: soát bằng máy theo các quy luật đo được – quy đổi m³/h ↔ l/min (×16,67), kW ↔ HP, cột áp tỉ lệ với số tầng, tổng chiều dài/khối lượng T = P + M, cột áp không tăng khi lưu lượng tăng; mọi ô nghi đều được phóng to kiểm lại bằng mắt trước khi ghi vào danh sách. 4) So chéo các bản cùng nội dung khác hãng (3 bản cắt rác, 2 bản KTZ-LH, 2 bản 3M, 2 bản CM, 2 bản CDLF, Perotac SA ↔ Redpump SL).
A6: MỨC ĐỘ | B6: 1-Nghiêm trọng: sai tên hãng hoặc sai thông số chính (cột áp, công suất, kích thước) dễ làm khách hiểu sai. 2-Lỗi: sai chữ, nhãn, quy đổi rõ ràng. 3-Cần anh xác nhận: có dấu hiệu sai nhưng cần tài liệu NCC hoặc quyết định của anh. 4-Nhỏ: trình bày, đơn vị, khoảng cách.
A7: SỐ "≈" | B7: Giá trị có dấu ≈ ở cột "Đề xuất sửa" là số tính từ các dòng cùng bảng (tỉ lệ theo tầng, cộng/trừ) để chỉ ra chỗ sai; nên đối chiếu bảng gốc của NCC trước khi chốt số cuối.
A8: GIỚI HẠN | B8: 3 file Perotac SA, Perotac SP, Redpump SL là ảnh nén 150 dpi: đã chép lại toàn bộ bảng và soát theo quy luật, nhưng chữ quá mờ ở vài ô vẫn có thể sót. File Excel: đã đọc trực tiếp giá trị và công thức các ô.
A9: LIÊN QUAN QUYẾT ĐỊNH TRƯỚC | B9: Các dòng ghi "Quyết định trước của anh" dựa trên điều anh đã chốt cho web: Aquaris bảo hành 24 tháng (27/09), Redpump ghi "Trung Quốc (tiêu chuẩn Ý)" (27/09), Perotac CDLF đế inox (25/09). Catalogue hiện ghi khác – anh quyết có sửa không.
